Traceback (most recent call last):
  File "/home/linares/miniconda3/envs/vlx-github/lib/python3.12/site-packages/nbclient/client.py", line 782, in _async_poll_for_reply
    msg = await ensure_async(self.kc.shell_channel.get_msg(timeout=new_timeout))
          ^^^^^^^^^^^^^^^^^^^^^^^^^^^^^^^^^^^^^^^^^^^^^^^^^^^^^^^^^^^^^^^^^^^^^^
  File "/home/linares/miniconda3/envs/vlx-github/lib/python3.12/site-packages/jupyter_core/utils/__init__.py", line 198, in ensure_async
    result = await obj
             ^^^^^^^^^
  File "/home/linares/miniconda3/envs/vlx-github/lib/python3.12/site-packages/jupyter_client/channels.py", line 313, in get_msg
    raise Empty
_queue.Empty

During handling of the above exception, another exception occurred:

Traceback (most recent call last):
  File "/home/linares/miniconda3/envs/vlx-github/lib/python3.12/site-packages/jupyter_cache/executors/utils.py", line 58, in single_nb_execution
    executenb(
  File "/home/linares/miniconda3/envs/vlx-github/lib/python3.12/site-packages/nbclient/client.py", line 1319, in execute
    return NotebookClient(nb=nb, resources=resources, km=km, **kwargs).execute()
           ^^^^^^^^^^^^^^^^^^^^^^^^^^^^^^^^^^^^^^^^^^^^^^^^^^^^^^^^^^^^^^^^^^^^^
  File "/home/linares/miniconda3/envs/vlx-github/lib/python3.12/site-packages/jupyter_core/utils/__init__.py", line 165, in wrapped
    return loop.run_until_complete(inner)
           ^^^^^^^^^^^^^^^^^^^^^^^^^^^^^^
  File "/home/linares/miniconda3/envs/vlx-github/lib/python3.12/asyncio/base_events.py", line 686, in run_until_complete
    return future.result()
           ^^^^^^^^^^^^^^^
  File "/home/linares/miniconda3/envs/vlx-github/lib/python3.12/site-packages/nbclient/client.py", line 709, in async_execute
    await self.async_execute_cell(
  File "/home/linares/miniconda3/envs/vlx-github/lib/python3.12/site-packages/nbclient/client.py", line 1005, in async_execute_cell
    exec_reply = await self.task_poll_for_reply
                 ^^^^^^^^^^^^^^^^^^^^^^^^^^^^^^
  File "/home/linares/miniconda3/envs/vlx-github/lib/python3.12/site-packages/nbclient/client.py", line 806, in _async_poll_for_reply
    error_on_timeout_execute_reply = await self._async_handle_timeout(timeout, cell)
                                     ^^^^^^^^^^^^^^^^^^^^^^^^^^^^^^^^^^^^^^^^^^^^^^^
  File "/home/linares/miniconda3/envs/vlx-github/lib/python3.12/site-packages/nbclient/client.py", line 856, in _async_handle_timeout
    raise CellTimeoutError.error_from_timeout_and_cell(
nbclient.exceptions.CellTimeoutError: A cell timed out while it was being executed, after 120 seconds.
The message was: Cell execution timed out.
Here is a preview of the cell contents:
-------------------
['solvationfep = vlx.SolvationFepDriver()', '', '# Optional, saving trajectory from each lambda simulation in xtc format ', '#solvationfep.save_trajectory_xtc = True ', '']
...
['# Notebook, we recommend using 500 000 steps for production runs (1 ns)', '# per Lambda.', 'solvationfep.num_steps = 10000', 'delta_f, final_energy =solvationfep.compute_solvation_from_gromacs_files(', "    'system.gro','system.top','ibuprof.gro','ibuprof.top')"]
-------------------

